Workbook
Name \a: #REF!
Name \b: #REF!
Name _: #REF!,#REF!,#REF!,#REF!,#REF!,#REF!,#REF!,#REF!,#REF!,#REF!
Name _: #REF!,#REF!,#REF!,#REF!,#REF!,#REF!,#REF!,#REF!,#REF!,#REF!
Name _: #REF!,#REF!,#REF!,#REF!,#REF!,#REF!,#REF!,#REF!,#REF!,#REF!
Name _: #REF!,#REF!,#REF!,#REF!,#REF!,#REF!,#REF!,#REF!,#REF!,#REF!
Name _: #REF!,#REF!,#REF!,#REF!,#REF!,#REF!,#REF!,#REF!,#REF!,#REF!
Name _: #REF!,#REF!,#REF!,#REF!,#REF!,#REF!,#REF!,#REF!,#REF!,#REF!
Name _: #REF!,#REF!,#REF!,#REF!,#REF!,#REF!,#REF!,#REF!,#REF!,#REF!
Name _: #REF!,#REF!,#REF!,#REF!,#REF!,#REF!,#REF!,#REF!,#REF!,#REF!
Name _: #REF!,#REF!,#REF!,#REF!,#REF!,#REF!,#REF!,#REF!,#REF!,#REF!
Name _: #REF!,#REF!,#REF!,#REF!,#REF!,#REF!,#REF!,#REF!,#REF!,#REF!
Name _: #REF!,#REF!,#REF!,#REF!,#REF!,#REF!,#REF!,#REF!,#REF!,#REF!
Name _: #REF!,#REF!,#REF!,#REF!,#REF!,#REF!,#REF!,#REF!,#REF!,#REF!
Name _: #REF!,#REF!,#REF!,#REF!,#REF!,#REF!,#REF!,#REF!,#REF!,#REF!
Name _: #REF!,#REF!,#REF!,#REF!,#REF!,#REF!,#REF!,#REF!,#REF!,#REF!
Name _: #REF!,#REF!,#REF!,#REF!,#REF!,#REF!,#REF!,#REF!,#REF!,#REF!
Name _: #REF!,#REF!,#REF!,#REF!,#REF!,#REF!,#REF!,#REF!,#REF!,#REF!
Name _: #REF!,#REF!,#REF!,#REF!,#REF!,#REF!,#REF!,#REF!,#REF!,#REF!
Name _: #REF!,#REF!,#REF!,#REF!,#REF!,#REF!,#REF!,#REF!,#REF!,#REF!
Name _: #REF!,#REF!,#REF!,#REF!,#REF!,#REF!,#REF!,#REF!,#REF!,#REF!
Name _: #REF!,#REF!,#REF!,#REF!,#REF!,#REF!,#REF!,#REF!,#REF!,#REF!
Name _: #REF!,#REF!,#REF!,#REF!,#REF!,#REF!,#REF!,#REF!,#REF!,#REF!
Name _: #REF!,#REF!,#REF!,#REF!,#REF!,#REF!,#REF!,#REF!,#REF!,#REF!
Name _: #REF!,#REF!,#REF!,#REF!,#REF!,#REF!,#REF!,#REF!,#REF!,#REF!
Name _: #REF!,#REF!,#REF!,#REF!,#REF!,#REF!,#REF!,#REF!,#REF!,#REF!
Name _: #REF!,#REF!,#REF!,#REF!,#REF!,#REF!,#REF!,#REF!,#REF!,#REF!
Name _: #REF!,#REF!,#REF!,#REF!,#REF!,#REF!,#REF!,#REF!,#REF!,#REF!
Name _: #REF!,#REF!,#REF!,#REF!,#REF!,#REF!,#REF!,#REF!,#REF!,#REF!
Name _: #REF!,#REF!,#REF!,#REF!,#REF!,#REF!,#REF!,#REF!,#REF!,#REF!
Name _: #REF!,#REF!,#REF!,#REF!,#REF!,#REF!,#REF!,#REF!,#REF!,#REF!
Name _: #REF!,#REF!,#REF!,#REF!,#REF!,#REF!,#REF!,#REF!,#REF!,#REF!
Name _: #REF!,#REF!,#REF!,#REF!,#REF!,#REF!,#REF!,#REF!,#REF!,#REF!
Name _: #REF!,#REF!,#REF!,#REF!,#REF!,#REF!,#REF!,#REF!,#REF!,#REF!
Name _: #REF!,#REF!,#REF!,#REF!,#REF!,#REF!,#REF!,#REF!,#REF!,#REF!
Name _: #REF!,#REF!,#REF!,#REF!,#REF!,#REF!,#REF!,#REF!,#REF!,#REF!
Name _______ISC3: #REF!+#REF!
Name _______ISC3: #REF!+#REF!
Name _______ISC3: #REF!+#REF!
Name _______ISC3: #REF!+#REF!
Name _______ISC3: #REF!+#REF!
Name _______ISC3: #REF!+#REF!
Name _______ISC3: #REF!+#REF!
Name _______ISC3: #REF!+#REF!
Name _______ISC3: #REF!+#REF!
Name _______ISC3: #REF!+#REF!
Name _______ISC3: #REF!+#REF!
Name _______ISC3: #REF!+#REF!
Name _______ISC3: #REF!+#REF!
Name _______ISC3: #REF!+#REF!
Name _______ISC3: #REF!+#REF!
Name _______ISC3: #REF!+#REF!
Name _______ISC3: #REF!+#REF!
Name _______ISC3: #REF!+#REF!
Name _______ISC3: #REF!+#REF!
Name _______ISC3: #REF!+#REF!
Name _______ISC3: #REF!+#REF!
Name _______ISC3: #REF!+#REF!
Name _______ISC3: #REF!+#REF!
Name _______ISC3: #REF!+#REF!

Sheet TOC
A1: TOC | B1: PISA 2022 Results. Mindsets, Attitudes and Learning: Exploring their connections among students - © OECD 2025
A3: Figures & Tables
A5: Figures
A7: ='Figure 1'!A1 -> Figure 1 | B7: ='Figure 1'!$A$2 -> Growth mindset: Change between PISA 2018 and PISA 2022 results
A8: ='Figure 2'!A1 -> Figure 2 | B8: ='Figure 2'!$A$2 -> Growth mindset and performance in mathematics
A9: ='Figure 3'!A1 -> Figure 3 | B9: ='Figure 3'!$A$2 -> Growth mindset by gender
A10: ='Figure 4'!A1 -> Figure 4 | B10: ='Figure 4'!$A$2 -> Growth mindset by student performance
A11: ='Figure 5'!A1 -> Figure 5 | B11: ='Figure 5'!$A$2 -> Growth mindset and mathematics performance, by student performance
A12: =Figure_6!A1 -> Figure_6 | B12: =Figure_6!$A$2 -> Interquartile difference of the relationship between growth mindset and performance in mathematics and share of low performers
A13: ='Figure 7'!A1 -> Figure 7 | B13: ='Figure 7'!$A$2 -> Growth mindset, self-belief and attitudes, by level of performance
A14: ='Figure 8'!A1 -> Figure 8 | B14: ='Figure 8'!$A$2 -> Growth mindset and confidence in self-directed learning, by level of performance
A15: =Figure_9!A1 -> Figure_9 | B15: =Figure_9!$A$2 -> Relationship between growth mindset, performance in mathematics and mathematics anxiety
A16: ='Figure 10'!A1 -> Figure 10 | B16: ='Figure 10'!$A$2 -> Growth mindset and performance in mathematics, by level of socio-emotional skills
A17: ='Figure 11'!A1 -> Figure 11 | B17: ='Figure 11'!$A$2 -> Growth mindset and teacher practices, by level of performance
A18: ='Figure 12'!A1 -> Figure 12 | B18: ='Figure 12'!$A$2 -> Growth mindset and performance in mathematics, by level of students' cognitive activation
A19: ='Figure 13'!A1 -> Figure 13 | B19: ='Figure 13'!$A$2 -> School concentration of growth mindset
A23: Tables
A25: ='Table B.1'!A1 -> Table B.1 | B25: ='Table B.1'!$A$2 -> Growth mindset, by level of performance in mathematics
A28: ='Table B.4'!A1 -> Table B.4 | B28: ='Table B.4'!$A$2 -> Change in growth mindset between PISA 2018 and PISA 2022
A29: ='Table B.5'!A1 -> Table B.5 | B29: ='Table B.5'!$A$2 -> Growth mindset and fixed mindset: Change between PISA 2018 and PISA 2022
A30: ='Table B.6'!A1 -> Table B.6 | B30: ='Table B.6'!$A$2 -> Growth mindset : school concentration
A31: ='Table B.7'!A1 -> Table B.7 | B31: ='Table B.7'!$A$2 -> Students' and schools' growth mindset
A32: ='Table B.8'!A1 -> Table B.8 | B32: ='Table B.8'!$A$2 -> Performance in mathematics and concentration of growth mindset in school
A33: ='Table B.9'!A1 -> Table B.9 | B33: ='Table B.9'!$A$2 -> Socio-economic status and concentration of growth mindset in school
A34: ='Table B.10'!A1 -> Table B.10 | B34: ='Table B.10'!$A$2 -> Growth mindset, by student characteristics
A35: ='Table B.11'!A1 -> Table B.11 | B35: ='Table B.11'!$A$2 -> Growth mindset by level of teacher practices
A36: ='Table B.12'!A1 -> Table B.12 | B36: ='Table B.12'!$A$2 -> Growth mindset and academic performance
A37: ='Table B.13'!A1 -> Table B.13 | B37: ='Table B.13'!$A$2 -> Standardised effect size of growth mindset in academic performance
A38: ='Table B.14'!A1 -> Table B.14 | B38: ='Table B.14'!$A$2 -> Growth mindset and performance in mathematics, by level of performance
A39: ='Table B.15'!A1 -> Table B.15 | B39: ='Table B.15'!$A$2 -> Standardised effect size of growth mindset in mathematics performance, by level of performance
A40: ='Table B.16'!A1 -> Table B.16 | B40: ='Table B.16'!$A$2 -> Growth mindset by variation in mathematics performance
A41: ='Table B.17'!A1 -> Table B.17 | B41: ='Table B.17'!$A$2 -> Growth mindset and mathematics performance, by student characteristics
A42: ='Table B.18'!A1 -> Table B.18 | B42: ='Table B.18'!$A$2 -> Standardised effect size of growth mindset in mathematics performance, by student characteristics
A43: ='Table B.19'!A1 -> Table B.19 | B43: ='Table B.19'!$A$2 -> Growth mindset and students attitudes, by level of performance in mathematics
A44: ='Table B.20'!A1 -> Table B.20 | B44: ='Table B.20'!$A$2 -> Standardised effect size of growth mindset in students attitudes, by level of performance in mathematics
A45: ='Table B.21'!A1 -> Table B.21 | B45: ='Table B.21'!$A$2 -> Growth mindset and social and emotionnal skills, by level of performance in mathematics
A46: ='Table B.22'!A1 -> Table B.22 | B46: ='Table B.22'!$A$2 -> Standardised effect size of growth mindset in social and emotionnal skills, by level of performance in mathematics
A47: ='Table B.23'!A1 -> Table B.23 | B47: ='Table B.23'!$A$2 -> Growth mindset and teacher practices, by level of performance in mathematics
A48: ='Table B.24'!A1 -> Table B.24 | B48: ='Table B.24'!$A$2 -> Standardised effect size of growth mindset in teacher practices, by level of performance in mathematics
A49: ='Table B.25'!A1 -> Table B.25 | B49: ='Table B.25'!$A$2 -> General growth mindset and mathematics performance, by quality of mathematics instruction
...

Sheet Figure 1
A1: Figure 1
A2: Growth mindset: Change between PISA 2018 and PISA 2022 results
A3: Change between 2018 and 2022 in the percentage of students disagreeing or strongly disagreeing that "your intelligence is something about you that you can't change very much"
A76: Notes: Only countries and economies with available data are shown.
A77: Statistically significant differences between PISA 2018 and PISA 2022 are shown in a darker tone (see Reader’s Guide).
A78: Countries and economies are ranked in descending order of the difference between PISA 2018 and PISA 2022 (PISA 2022 minus PISA 2018).
A79: Source: OECD, PISA 2022 Database, Table B.5.
B85: PISA 2018 | D85: PISA 2022
B86: Significant change | C86: Non-significant change | D86: Significant change | E86: Non-significant change
B87: % | C87: % | D87: % | E87: % | M87: spacing | N87: positive error | O87: negative error | P87: CNT | Q87: Sub-nat entities
A88: North Macedonia | B88: 23.998341 | C88: #N/A | D88: 39.977821 | E88: #N/A | L88: 15.979481 | M88: 68.5 | N88: 0 | O88: 15.979481 | P88: 0 | Q88: #N/A
A89: Poland | B89: 40.714336 | C89: #N/A | D89: 53.373837 | E89: #N/A | L89: 12.6595 | M89: 67.5 | N89: 0 | O89: 12.6595 | P89: 0 | Q89: #N/A
A90: Kazakhstan | B90: 55.005043 | C90: #N/A | D90: 66.872345 | E90: #N/A | L90: 11.867302 | M90: 66.5 | N90: 0 | O90: 11.867302 | P90: 0 | Q90: #N/A
A91: Panama* | B91: 28.725292 | C91: #N/A | D91: 39.536709 | E91: #N/A | L91: 10.811417 | M91: 65.5 | N91: 0 | O91: 10.811417 | P91: 0 | Q91: #N/A
A92: Sweden | B92: 62.89999 | C92: #N/A | D92: 70.449242 | E92: #N/A | L92: 7.5492516 | M92: 64.5 | N92: 0 | O92: 7.5492516 | P92: 0 | Q92: #N/A
A93: Georgia | B93: 49.586693 | C93: #N/A | D93: 56.778984 | E93: #N/A | L93: 7.1922913 | M93: 63.5 | N93: 0 | O93: 7.1922913 | P93: 0 | Q93: #N/A
A94: Morocco | B94: 41.510754 | C94: #N/A | D94: 48.526825 | E94: #N/A | L94: 7.0160713 | M94: 62.5 | N94: 0 | O94: 7.0160713 | P94: 0 | Q94: #N/A
A95: Indonesia | B95: 28.546738 | C95: #N/A | D95: 35.371799 | E95: #N/A | L95: 6.8250618 | M95: 61.5 | N95: 0 | O95: 6.8250618 | P95: 0 | Q95: #N/A
A96: Kosovo | B96: 27.608772 | C96: #N/A | D96: 33.852093 | E96: #N/A | L96: 6.2433205 | M96: 60.5 | N96: 0 | O96: 6.2433205 | P96: #N/A | Q96: 0
A97: Thailand | B97: 42.832123 | C97: #N/A | D97: 48.186909 | E97: #N/A | L97: 5.3547859 | M97: 59.5 | N97: 0 | O97: 5.3547859 | P97: 0 | Q97: #N/A
A98: Japan | B98: 66.928612 | C98: #N/A | D98: 71.003937 | E98: #N/A | L98: 4.075325 | M98: 58.5 | N98: 0 | O98: 4.075325 | P98: 0 | Q98: #N/A
A99: Philippines | B99: 31.316027 | C99: #N/A | D99: 35.349842 | E99: #N/A | L99: 4.0338154 | M99: 57.5 | N99: 0 | O99: 4.0338154 | P99: 0 | Q99: #N/A
A100: United Arab Emirates | B100: 45.909645 | C100: #N/A | D100: 49.564198 | E100: #N/A | L100: 3.6545525 | M100: 56.5 | N100: 0 | O100: 3.6545525 | P100: 0 | Q100: #N/A
A101: Dominican Republic | B101: 34.673862 | C101: #N/A | D101: 38.154385 | E101: #N/A | L101: 3.4805222 | M101: 55.5 | N101: 0 | O101: 3.4805222 | P101: 0 | Q101: #N/A
A102: Jordan | B102: #N/A | C102: 47.032082 | D102: #N/A | E102: 49.094429 | L102: 2.0623474 | M102: 54.5 | N102: 0 | O102: 2.0623474 | P102: 0 | Q102: #N/A
A103: Montenegro | B103: 45.496025 | C103: #N/A | D103: 47.50074 | E103: #N/A | L103: 2.004715 | M103: 53.5 | N103: 0 | O103: 2.004715 | P103: 0 | Q103: #N/A
A104: United States* | B104: #N/A | C104: 68.388939 | D104: #N/A | E104: 69.782112 | L104: 1.3931732 | M104: 52.5 | N104: 0 | O104: 1.3931732 | P104: 0 | Q104: #N/A
A105: Korea | B105: #N/A | C105: 53.299793 | D105: #N/A | E105: 54.531029 | L105: 1.2312355 | M105: 51.5 | N105: 0 | O105: 1.2312355 | P105: 0 | Q105: #N/A
A106: Singapore | B106: #N/A | C106: 59.973221 | D106: #N/A | E106: 60.869297 | L106: 0.8960762 | M106: 50.5 | N106: 0 | O106: 0.8960762 | P106: 0 | Q106: #N/A
A107: Chile | B107: #N/A | C107: 60.313835 | D107: #N/A | E107: 61.190243 | L107: 0.87640762 | M107: 49.5 | N107: 0 | O107: 0.87640762 | P107: 0 | Q107: #N/A
A108: Slovenia | B108: #N/A | C108: 51.476551 | D108: #N/A | E108: 52.139442 | L108: 0.66289139 | M108: 48.5 | N108: 0 | O108: 0.66289139 | P108: 0 | Q108: #N/A
A109: Bulgaria | B109: #N/A | C109: 59.321388 | D109: #N/A | E109: 58.969883 | L109: -0.35150528 | M109: 47.5 | N109: 0.35150528 | O109: 0 | P109: 0 | Q109: #N/A
A110: Romania | B110: #N/A | C110: 43.225315 | D110: #N/A | E110: 42.830715 | L110: -0.39459991 | M110: 46.5 | N110: 0.39459991 | O110: 0 | P110: 0 | Q110: #N/A
A111: Costa Rica | B111: #N/A | C111: 54.332981 | D111: #N/A | E111: 53.885674 | L111: -0.44730759 | M111: 45.5 | N111: 0.44730759 | O111: 0 | P111: 0 | Q111: #N/A
A112: Austria | B112: #N/A | C112: 71.999207 | D112: #N/A | E112: 71.463753 | L112: -0.5354538 | M112: 44.5 | N112: 0.5354538 | O112: 0 | P112: 0 | Q112: #N/A
A113: Serbia | B113: #N/A | C113: 52.115967 | D113: #N/A | E113: 51.265095 | L113: -0.85087204 | M113: 43.5 | N113: 0.85087204 | O113: 0 | P113: 0 | Q113: #N/A
A114: Ireland* | B114: #N/A | C114: 73.909912 | D114: #N/A | E114: 72.882996 | L114: -1.0269165 | M114: 42.5 | N114: 1.0269165 | O114: 0 | P114: 0 | Q114: #N/A
A115: Slovak Republic | B115: #N/A | C115: 57.182735 | D115: #N/A | E115: 56.103233 | L115: -1.0795021 | M115: 41.5 | N115: 1.0795021 | O115: 0 | P115: 0 | Q115: #N/A
... A118: Germany | B118: #N/A | C118: 73.98539 | D118: #N/A | E118: 72.137985 | L118: -1.8474045 | M118: 38.5 | N118: 1.8474045 | O118: 0 | P118: 0 | Q118: #N/A
A119: New Zealand* | B119: 67.149208 | C119: #N/A | D119: 65.108574 | E119: #N/A | L119: -2.0406342 | M119: 37.5 | N119: 2.0406342 | O119: 0 | P119: 0 | Q119: #N/A
...

Sheet Figure 2
A1: Figure 2
A2: Growth mindset and performance in mathematics
A3: Change in mathematics performance when students disagreed or strongly disagreed that "your intelligence is something about you that you can’t change very much"
A76: 1. The socio-economic profile is measured by the PISA index of economic, social and cultural status (ESCS).
A77: Notes: Only countries and economies with available data are shown.
A78: Coefficients that are statistically significant are shown in a darker tone (see Reader’s Guide).
A79: Countries and economies are ranked in descending order of the gap in mathematics performance related to general growth mindset, before accounting for students' and schools' socio-economic profile.
A80: Source: OECD, PISA 2022 Database, Table B.12.
B86: Before accounting for students' and schools' socio-economic profile¹ | D86: After accounting for students' and schools' socio-economic profile
B87: Significant change | C87: Non-significant change | D87: Significant change | E87: Non-significant change
B88: Score dif. | C88: Score dif. | D88: Score dif. | E88: Score dif. | L88: aft | M88: spacing | N88: positive error | O88: negative error | P88: CNT | Q88: Sub-nat entities
A89: Australia* | B89: 59.239803 | C89: #N/A | D89: 45.418575 | E89: #N/A | L89: 45.418575 | M89: 74.5 | N89: 0 | O89: 45.418575 | P89: -10 | Q89: #N/A
A90: United States* | B90: 57.199528 | C90: #N/A | D90: 46.213791 | E90: #N/A | L90: 46.213791 | M90: 73.5 | N90: 0 | O90: 46.213791 | P90: -10 | Q90: #N/A
A91: New Zealand* | B91: 51.545612 | C91: #N/A | D91: 40.077248 | E91: #N/A | L91: 40.077248 | M91: 72.5 | N91: 0 | O91: 40.077248 | P91: -10 | Q91: #N/A
A92: United Arab Emirates | B92: 46.050735 | C92: #N/A | D92: 34.417427 | E92: #N/A | L92: 34.417427 | M92: 71.5 | N92: 0 | O92: 34.417427 | P92: -10 | Q92: #N/A
A93: Ireland* | B93: 45.874519 | C93: #N/A | D93: 39.72047 | E93: #N/A | L93: 39.72047 | M93: 70.5 | N93: 0 | O93: 39.72047 | P93: -10 | Q93: #N/A
A94: United Kingdom* | B94: 45.30896 | C94: #N/A | D94: 36.14764 | E94: #N/A | L94: 36.14764 | M94: 69.5 | N94: 0 | O94: 36.14764 | P94: -10 | Q94: #N/A
A95: Brazil | B95: 41.547523 | C95: #N/A | D95: 28.510063 | E95: #N/A | L95: 28.510063 | M95: 68.5 | N95: 0 | O95: 28.510063 | P95: -10 | Q95: #N/A
A96: Chile | B96: 38.899258 | C96: #N/A | D96: 29.773602 | E96: #N/A | L96: 29.773602 | M96: 67.5 | N96: 0 | O96: 29.773602 | P96: -10 | Q96: #N/A
A97: Jamaica* | B97: 36.699448 | C97: #N/A | D97: 21.086006 | E97: #N/A | L97: 21.086006 | M97: 66.5 | N97: 0 | O97: 21.086006 | P97: -10 | Q97: #N/A
A98: Canada* | B98: 36.611263 | C98: #N/A | D98: 29.953909 | E98: #N/A | L98: 29.953909 | M98: 65.5 | N98: 0 | O98: 29.953909 | P98: -10 | Q98: #N/A
A99: Singapore | B99: 35.67968 | C99: #N/A | D99: 27.922785 | E99: #N/A | L99: 27.922785 | M99: 64.5 | N99: 0 | O99: 27.922785 | P99: -10 | Q99: #N/A
A100: Portugal | B100: 35.590942 | C100: #N/A | D100: 26.188253 | E100: #N/A | L100: 26.188253 | M100: 63.5 | N100: 0 | O100: 26.188253 | P100: -10 | Q100: #N/A
... A111: Uruguay | B111: 26.849573 | C111: #N/A | D111: 18.900703 | E111: #N/A | L111: 18.900703 | M111: 52.5 | N111: 0 | O111: 18.900703 | P111: -10 | Q111: #N/A
A112: Ukrainian regions (18 of 27) | B112: 26.155741 | C112: #N/A | D112: 18.903852 | E112: #N/A | L112: 18.903852 | M112: 51.5 | N112: 0 | O112: 18.903852 | P112: #N/A | Q112: -10
A113: Iceland | B113: 25.606808 | C113: #N/A | D113: 21.484142 | E113: #N/A | L113: 21.484142 | M113: 50.5 | N113: 0 | O113: 21.484142 | P113: -10 | Q113: #N/A
A114: Latvia* | B114: 25.410553 | C114: #N/A | D114: 18.90781 | E114: #N/A | L114: 18.90781 | M114: 49.5 | N114: 0 | O114: 18.90781 | P114: -10 | Q114: #N/A
A115: Austria | B115: 24.623915 | C115: #N/A | D115: 17.255558 | E115: #N/A | L115: 17.255558 | M115: 48.5 | N115: 0 | O115: 17.255558 | P115: -10 | Q115: #N/A
A116: Indonesia | B116: 24.616173 | C116: #N/A | D116: 20.06052 | E116: #N/A | L116: 20.06052 | M116: 47.5 | N116: 0 | O116: 20.06052 | P116: -10 | Q116: #N/A
A117: Panama* | B117: 24.111849 | C117: #N/A | D117: 11.52669 | E117: #N/A | L117: 11.52669 | M117: 46.5 | N117: 0 | O117: 11.52669 | P117: -10 | Q117: #N/A
A118: OECD average | B118: 24.014006 | C118: #N/A | D118: 17.575439 | E118: #N/A | L118: 17.575439 | M118: 45.5 | N118: 0 | O118: 17.575439 | P118: -10 | Q118: #N/A
A119: Japan | B119: 23.645828 | C119: #N/A | D119: 13.971684 | E119: #N/A | L119: 13.971684 | M119: 44.5 | N119: 0 | O119: 13.971684 | P119: -10 | Q119: #N/A
A120: Mexico | B120: 23.378365 | C120: #N/A | D120: 16.842495 | E120: #N/A | L120: 16.842495 | M120: 43.5 | N120: 0 | O120: 16.842495 | P120: -10 | Q120: #N/A
A121: Thailand | B121: 22.930359 | C121: #N/A | D121: 17.336233 | E121: #N/A | L121: 17.336233 | M121: 42.5 | N121: 0 | O121: 17.336233 | P121: -10 | Q121: #N/A
A122: Hungary | B122: 22.805046 | C122: #N/A | D122: 8.8286819 | E122: #N/A | L122: 8.8286819 | M122: 41.5 | N122: 0 | O122: 8.8286819 | P122: -10 | Q122: #N/A
A123: Mongolia | B123: 21.31426 | C123: #N/A | D123: 14.92372 | E123: #N/A | L123: 14.92372 | M123: 40.5 | N123: 0 | O123: 14.92372 | P123: -10 | Q123: #N/A
A124: Slovenia | B124: 21.260256 | C124: #N/A | D124: 8.7380486 | E124: #N/A | L124: 8.7380486 | M124: 39.5 | N124: 0 | O124: 8.7380486 | P124: -10 | Q124: #N/A
... A129: Finland | B129: 17.953138 | C129: #N/A | D129: 13.814286 | E129: #N/A | L129: 13.814286 | M129: 34.5 | N129: 0 | O129: 13.814286 | P129: -10 | Q129: #N/A
A130: Bulgaria | B130: 17.551321 | C130: #N/A | D130: #N/A | E130: 4.7023802 | L130: 4.7023802 | M130: 33.5 | N130: 0 | O130: 4.7023802 | P130: -10 | Q130: #N/A
A131: Lithuania | B131: 17.446703 | C131: #N/A | D131: 8.2641249 | E131: #N/A | L131: 8.2641249 | M131: 32.5 | N131: 0 | O131: 8.2641249 | P131: -10 | Q131: #N/A
...

Sheet Figure 3
A1: Figure 3
A2: Growth mindset by gender
A3: Percentage of students disagreeing or strongly disagreeing that "your intelligence is something about you that you can't change very much", by gender
A76: Notes: Only countries and economies with available data are shown.
A77: Statistically significant differences between boys and girls are shown in a darker tone (see Reader’s Guide).
A78: Countries and economies are ranked in descending order of the difference between boys and girls.
A79: Source: OECD, PISA 2022 Database, Table B.10.
B85: Girls | D85: Boys
B86: Significant change | C86: Non-significant change | D86: Significant change | E86: Non-significant change
B87: % | C87: % | D87: % | E87: % | M87: spacing | N87: positive error | O87: negative error | P87: CNT | Q87: Sub-nat entities
A88: Dominican Republic | B88: 33.442963 | C88: #N/A | D88: 43.841732 | E88: #N/A | L88: 10.398769 | M88: 75.5 | N88: 0 | O88: 10.398769 | P88: 0 | Q88: #N/A
A89: Uruguay | B89: 47.674374 | C89: #N/A | D89: 56.744865 | E89: #N/A | L89: 9.0704918 | M89: 74.5 | N89: 0 | O89: 9.0704918 | P89: 0 | Q89: #N/A
A90: Qatar | B90: 41.656601 | C90: #N/A | D90: 49.662678 | E90: #N/A | L90: 8.0060768 | M90: 73.5 | N90: 0 | O90: 8.0060768 | P90: 0 | Q90: #N/A
A91: Jamaica* | B91: 31.91021 | C91: #N/A | D91: 39.606514 | E91: #N/A | L91: 7.6963043 | M91: 72.5 | N91: 0 | O91: 7.6963043 | P91: 0 | Q91: #N/A
A92: Moldova | B92: 30.426281 | C92: #N/A | D92: 37.448593 | E92: #N/A | L92: 7.0223122 | M92: 71.5 | N92: 0 | O92: 7.0223122 | P92: 0 | Q92: #N/A
A93: Peru | B93: 40.138439 | C93: #N/A | D93: 47.042675 | E93: #N/A | L93: 6.9042358 | M93: 70.5 | N93: 0 | O93: 6.9042358 | P93: 0 | Q93: #N/A
A94: Morocco | B94: 45.481415 | C94: #N/A | D94: 51.607574 | E94: #N/A | L94: 6.1261597 | M94: 69.5 | N94: 0 | O94: 6.1261597 | P94: 0 | Q94: #N/A
A95: Hong Kong (China)* | B95: 36.874767 | C95: #N/A | D95: 42.947182 | E95: #N/A | L95: 6.0724144 | M95: 68.5 | N95: 0 | O95: 6.0724144 | P95: #N/A | Q95: 0
A96: El Salvador | B96: 32.969898 | C96: #N/A | D96: 38.852612 | E96: #N/A | L96: 5.8827133 | M96: 67.5 | N96: 0 | O96: 5.8827133 | P96: 0 | Q96: #N/A
A97: Panama* | B97: 36.618488 | C97: #N/A | D97: 42.48959 | E97: #N/A | L97: 5.8711014 | M97: 66.5 | N97: 0 | O97: 5.8711014 | P97: 0 | Q97: #N/A
A98: Albania | B98: 28.021019 | C98: #N/A | D98: 33.802288 | E98: #N/A | L98: 5.7812691 | M98: 65.5 | N98: 0 | O98: 5.7812691 | P98: 0 | Q98: #N/A
A99: Jordan | B99: 46.688061 | C99: #N/A | D99: 52.376884 | E99: #N/A | L99: 5.6888237 | M99: 64.5 | N99: 0 | O99: 5.6888237 | P99: 0 | Q99: #N/A
A100: Palestinian Authority | B100: 38.391392 | C100: #N/A | D100: 43.837646 | E100: #N/A | L100: 5.4462547 | M100: 63.5 | N100: 0 | O100: 5.4462547 | P100: #N/A | Q100: 0
A101: Macao (China) | B101: 38.195118 | C101: #N/A | D101: 43.327972 | E101: #N/A | L101: 5.1328545 | M101: 62.5 | N101: 0 | O101: 5.1328545 | P101: #N/A | Q101: 0
A102: North Macedonia | B102: 37.754097 | C102: #N/A | D102: 42.254517 | E102: #N/A | L102: 4.5004196 | M102: 61.5 | N102: 0 | O102: 4.5004196 | P102: 0 | Q102: #N/A
A103: Kosovo | B103: 31.739868 | C103: #N/A | D103: 36.236782 | E103: #N/A | L103: 4.4969139 | M103: 60.5 | N103: 0 | O103: 4.4969139 | P103: #N/A | Q103: 0
A104: Malaysia | B104: 35.989239 | C104: #N/A | D104: 40.324039 | E104: #N/A | L104: 4.3348007 | M104: 59.5 | N104: 0 | O104: 4.3348007 | P104: 0 | Q104: #N/A
A105: Thailand | B105: 46.16024 | C105: #N/A | D105: 50.423557 | E105: #N/A | L105: 4.2633171 | M105: 58.5 | N105: 0 | O105: 4.2633171 | P105: 0 | Q105: #N/A
A106: Uzbekistan | B106: 50.200779 | C106: #N/A | D106: 54.363419 | E106: #N/A | L106: 4.1626396 | M106: 57.5 | N106: 0 | O106: 4.1626396 | P106: 0 | Q106: #N/A
A107: Japan | B107: 69.06263 | C107: #N/A | D107: 72.971626 | E107: #N/A | L107: 3.9089966 | M107: 56.5 | N107: 0 | O107: 3.9089966 | P107: 0 | Q107: #N/A
A108: Philippines | B108: 33.435917 | C108: #N/A | D108: 37.327278 | E108: #N/A | L108: 3.8913612 | M108: 55.5 | N108: 0 | O108: 3.8913612 | P108: 0 | Q108: #N/A
A109: Chinese Taipei | B109: 52.960289 | C109: #N/A | D109: 56.791771 | E109: #N/A | L109: 3.8314819 | M109: 54.5 | N109: 0 | O109: 3.8314819 | P109: #N/A | Q109: 0
A110: Iceland | B110: 54.986599 | C110: #N/A | D110: 58.795895 | E110: #N/A | L110: 3.8092957 | M110: 53.5 | N110: 0 | O110: 3.8092957 | P110: 0 | Q110: #N/A
A111: Indonesia | B111: 33.591427 | C111: #N/A | D111: 37.262836 | E111: #N/A | L111: 3.6714096 | M111: 52.5 | N111: 0 | O111: 3.6714096 | P111: 0 | Q111: #N/A
A112: United Arab Emirates | B112: 47.846729 | C112: #N/A | D112: 51.392029 | E112: #N/A | L112: 3.5452995 | M112: 51.5 | N112: 0 | O112: 3.5452995 | P112: 0 | Q112: #N/A
A113: Mexico | B113: 40.084755 | C113: #N/A | D113: 43.233597 | E113: #N/A | L113: 3.1488419 | M113: 50.5 | N113: 0 | O113: 3.1488419 | P113: 0 | Q113: #N/A
A114: Baku (Azerbaijan) | B114: 41.782093 | C114: #N/A | D114: 44.906277 | E114: #N/A | L114: 3.1241837 | M114: 49.5 | N114: 0 | O114: 3.1241837 | P114: #N/A | Q114: 0
A115: Colombia | B115: 41.154316 | C115: #N/A | D115: 44.092396 | E115: #N/A | L115: 2.9380798 | M115: 48.5 | N115: 0 | O115: 2.9380798 | P115: 0 | Q115: #N/A
A116: Korea | B116: 53.034592 | C116: #N/A | D116: 55.90126 | E116: #N/A | L116: 2.8666687 | M116: 47.5 | N116: 0 | O116: 2.8666687 | P116: 0 | Q116: #N/A
A117: Saudi Arabia | B117: 39.500271 | C117: #N/A | D117: 42.358944 | E117: #N/A | L117: 2.8586731 | M117: 46.5 | N117: 0 | O117: 2.8586731 | P117: 0 | Q117: #N/A
...

Sheet Figure 4
A1: Figure 4
A2: Growth mindset by student performance
A3: Percentage of students disagreeing or strongly disagreeing that "your intelligence is something about you that you can't change very much", by level of performance in mathematics
A76: Notes: Only countries and economies with available data are shown.
A77: Countries and economies are ranked in descending order of the percentage of students disagreeing or strongly disagreeing that "your intelligence is something about you that you can't change very much" among mid performers in mathematics.
A78: Source: OECD, PISA 2022 Database, Table B.1.
B84: Low performers | C84: Mid performers | D84: Top performers
B85: % | C85: % | D85: % | J85: Min | K85: Max | L85: spacing | M85: positive error | N85: negative error | O85: CNT | P85: Sub-nat entities
A86: Brazil | B86: 53.805759 | C86: 78.032936 | D86: 84.415092 | J86: 53.805759 | K86: 84.415092 | L86: 75.5 | M86: 6.3821564 | N86: 24.227177 | O86: 0 | P86: #N/A
A87: United States* | B87: 53.017178 | C87: 76.783897 | D87: 85.115784 | J87: 53.017178 | K87: 85.115784 | L87: 74.5 | M87: 8.3318863 | N87: 23.76672 | O87: 0 | P87: #N/A
A88: Ireland* | B88: 53.013702 | C88: 76.264961 | D88: 87.294975 | J88: 53.013702 | K88: 87.294975 | L88: 73.5 | M88: 11.030014 | N88: 23.251259 | O88: 0 | P88: #N/A
A89: Germany | B89: 64.609779 | C89: 75.185158 | D89: 70.618919 | J89: 64.609779 | K89: 75.185158 | L89: 72.5 | M89: 0 | N89: 10.575378 | O89: 0 | P89: #N/A
A90: Estonia | B90: 61.168625 | C90: 75.152298 | D90: 80.405556 | J90: 61.168625 | K90: 80.405556 | L90: 71.5 | M90: 5.2532578 | N90: 13.983673 | O90: 0 | P90: #N/A
A91: Austria | B91: 60.292931 | C91: 74.320839 | D91: 76.464394 | J91: 60.292931 | K91: 76.464394 | L91: 70.5 | M91: 2.1435547 | N91: 14.027908 | O91: 0 | P91: #N/A
A92: Chile | B92: 50.924793 | C92: 72.237434 | D92: 71.144699 | J92: 50.924793 | K92: 72.237434 | L92: 69.5 | M92: 0 | N92: 21.312641 | O92: 0 | P92: #N/A
A93: Sweden | B93: 64.013023 | C93: 71.941772 | D93: 75.388901 | J93: 64.013023 | K93: 75.388901 | L93: 68.5 | M93: 3.4471283 | N93: 7.9287491 | O93: 0 | P93: #N/A
A94: Kazakhstan | B94: 62.982327 | C94: 70.248459 | D94: 81.801491 | J94: 62.982327 | K94: 81.801491 | L94: 67.5 | M94: 11.553032 | N94: 7.2661324 | O94: 0 | P94: #N/A
A95: Japan | B95: 62.377178 | C95: 69.89534 | D95: 78.492241 | J95: 62.377178 | K95: 78.492241 | L95: 66.5 | M95: 8.5969009 | N95: 7.5181618 | O95: 0 | P95: #N/A
A96: Australia* | B96: 46.098351 | C96: 69.642349 | D96: 84.231888 | J96: 46.098351 | K96: 84.231888 | L96: 65.5 | M96: 14.589539 | N96: 23.543999 | O96: 0 | P96: #N/A
A97: New Zealand* | B97: 47.510067 | C97: 69.235847 | D97: 80.52478 | J97: 47.510067 | K97: 80.52478 | L97: 64.5 | M97: 11.288933 | N97: 21.72578 | O97: 0 | P97: #N/A
A98: Costa Rica | B98: 47.839603 | C98: 68.884697 | D98: #N/A | J98: 47.839603 | K98: 68.884697 | L98: 63.5 | M98: 0 | N98: 21.045094 | O98: 0 | P98: #N/A
A99: United Kingdom* | B99: 46.781807 | C99: 66.640175 | D99: 76.899162 | J99: 46.781807 | K99: 76.899162 | L99: 62.5 | M99: 10.258987 | N99: 19.858368 | O99: 0 | P99: #N/A
A100: Denmark* | B100: 46.837204 | C100: 65.136452 | D100: 74.945816 | J100: 46.837204 | K100: 74.945816 | L100: 61.5 | M100: 9.8093643 | N100: 18.299248 | O100: 0 | P100: #N/A
A101: Ukrainian regions (18 of 27) | B101: 51.001781 | C101: 64.610657 | D101: 69.719261 | J101: 51.001781 | K101: 69.719261 | L101: 60.5 | M101: 5.1086044 | N101: 13.608875 | O101: #N/A | P101: 0
A102: Canada* | B102: 46.8974 | C102: 64.250992 | D102: 74.611961 | J102: 46.8974 | K102: 74.611961 | L102: 59.5 | M102: 10.36097 | N102: 17.353592 | O102: 0 | P102: #N/A
A103: Georgia | B103: 52.367832 | C103: 63.232983 | D103: 72.940918 | J103: 52.367832 | K103: 72.940918 | L103: 58.5 | M103: 9.7079353 | N103: 10.86515 | O103: 0 | P103: #N/A
A104: Bulgaria | B104: 54.714405 | C104: 62.626961 | D104: 67.092064 | J104: 54.714405 | K104: 67.092064 | L104: 57.5 | M104: 4.4651031 | N104: 7.9125557 | O104: 0 | P104: #N/A
A105: Switzerland | B105: 55.176128 | C105: 62.419998 | D105: 61.995872 | J105: 55.176128 | K105: 62.419998 | L105: 56.5 | M105: 0 | N105: 7.2438698 | O105: 0 | P105: #N/A
A106: Norway | B106: 49.890221 | C106: 60.97525 | D106: 70.683022 | J106: 49.890221 | K106: 70.683022 | L106: 55.5 | M106: 9.7077713 | N106: 11.08503 | O106: 0 | P106: #N/A
A107: OECD average | B107: 49.106384 | C107: 60.916706 | D107: 66.773613 | J107: 49.106384 | K107: 66.773613 | L107: 54.5 | M107: 5.8569069 | N107: 11.810322 | O107: 0 | P107: #N/A
A108: Argentina | B108: 42.174183 | C108: 60.266388 | D108: 63.743206 | J108: 42.174183 | K108: 63.743206 | L108: 53.5 | M108: 3.4768181 | N108: 18.092205 | O108: 0 | P108: #N/A
A109: Finland | B109: 52.405182 | C109: 60.244453 | D109: 67.516006 | J109: 52.405182 | K109: 67.516006 | L109: 52.5 | M109: 7.271553 | N109: 7.8392715 | O109: 0 | P109: #N/A
A110: Singapore | B110: 36.326256 | C110: 59.756855 | D110: 67.025429 | J110: 36.326256 | K110: 67.025429 | L110: 51.5 | M110: 7.2685738 | N110: 23.430599 | O110: 0 | P110: #N/A
A111: Latvia* | B111: 49.746975 | C111: 59.756783 | D111: 76.859016 | J111: 49.746975 | K111: 76.859016 | L111: 50.5 | M111: 17.102234 | N111: 10.009808 | O111: 0 | P111: #N/A
A112: Portugal | B112: 39.066517 | C112: 59.469982 | D112: 65.101509 | J112: 39.066517 | K112: 65.101509 | L112: 49.5 | M112: 5.6315269 | N112: 20.403465 | O112: 0 | P112: #N/A
A113: Uruguay | B113: 44.587399 | C113: 59.440762 | D113: 71.526741 | J113: 44.587399 | K113: 71.526741 | L113: 48.5 | M113: 12.085979 | N113: 14.853363 | O113: 0 | P113: #N/A
... A117: Iceland | B117: 50.011723 | C117: 58.459023 | D117: 73.355843 | J117: 50.011723 | K117: 73.355843 | L117: 44.5 | M117: 14.89682 | N117: 8.4473 | O117: 0 | P117: #N/A
A118: Chinese Taipei | B118: 46.065308 | C118: 57.534084 | D118: 54.487564 | J118: 46.065308 | K118: 57.534084 | L118: 43.5 | M118: 0 | N118: 11.468777 | O118: #N/A | P118: 0
A119: Slovak Republic | B119: 51.443287 | C119: 57.479416 | D119: 62.398907 | J119: 51.443287 | K119: 62.398907 | L119: 42.5 | M119: 4.9194908 | N119: 6.036129 | O119: 0 | P119: #N/A
A120: Croatia | B120: 48.579041 | C120: 56.655346 | D120: 57.068066 | J120: 48.579041 | K120: 57.068066 | L120: 41.5 | M120: 0.41271973 | N120: 8.0763054 | O120: 0 | P120: #N/A
...

Sheet Figure 5
A1: Figure 5
A2: Growth mindset and mathematics performance, by student performance
A3: Change in mathematics performance when students disagreed or strongly disagreed that "your intelligence is something about you that you can’t change very much", by level of performance in mathematics; OECD average
A35: 1. The socio-economic profile is measured by the PISA index of economic, social and cultural status (ESCS).
A36: Note: Coefficients that are statistically significant are shown in a darker tone (see Reader’s Guide).
A37: Source: OECD, PISA 2022 Database, Table B.14.
B40: Before accounting for students' and schools' socio-economic profile¹ | D40: After accounting for students' and schools' socio-economic profile
B41: Significant change | C41: Non-significant change | D41: Significant change | E41: Non-significant change
B42: Score dif. | C42: Score dif. | D42: Score dif. | E42: Score dif.
A43: Low performers (Below Level 2) | B43: 2.009995 | C43: #N/A | D43: 1.571463 | E43: #N/A
A44: Mid performers (Between Levels 2 to 4) | B44: 9.5042572 | C44: #N/A | D44: 8.129281 | E44: #N/A
A45: Top performers (Level 5 and above) | B45: #N/A | C45: -0.32784528 | D45: #N/A | E45: -0.37899998

Sheet Figure_6
A1: Figure_6
A2: Interquartile difference of the relationship between growth mindset and performance in mathematics and share of low performers
A48: Note: Only countries and economies with available data are shown.
A49: The interquartile difference (IQD) is defined as the gap between the estimated coefficients at the 75th and 25th percentiles of the performance distribution.
A50: Source: OECD, PISA 2022 Database, Tables I.B1.3.1 and B.16.
A52: Information on data for Cyprus: https://oe.cd/cyprus-disclaimer
B53: Interquartile difference | C53: Low performers in mathematics
B54: Score dif. | C54: %
A55: Albania | B55: 19.1713 | C55: 73.94312 | E55: 0 | F55: -0.19576944
A56: United Arab Emirates | B56: 43.4923 | C56: 48.99965 | E56: 100 | F56: -0.19576944
A57: Argentina | B57: 11.8482 | C57: 72.930062
A58: Australia* | B58: 7.6299 | C58: 26.342831 | E58: -40 | F58: 30.920508
A59: Austria | B59: -17.8755 | C59: 24.861008 | E59: 60 | F59: 30.920508
A60: Belgium | B60: -4.3833 | C60: 24.954413
A61: Bulgaria | B61: 8.1784 | C61: 53.599821
A62: Brazil | B62: 24.0441 | C62: 73.381533
A63: Brunei Darussalam | B63: 35.5395 | C63: 41.896361
A64: Canada* | B64: -3.7705 | C64: 21.625724
A65: Switzerland | B65: -10.863 | C65: 19.457551
A66: Chile | B66: 11.0885 | C66: 55.709621
A67: Colombia | B67: 17.2357 | C67: 71.22023
A68: Costa Rica | B68: 3.4777 | C68: 71.836952
A69: Czechia | B69: -9.8787 | C69: 25.523958
A70: Germany | B70: -20.185 | C70: 29.505209
A71: Denmark* | B71: -4.1209 | C71: 20.434414
... A132: OECD average | B132: -0.19576944 | C132: 30.920508

Sheet Figure 7
A1: Figure 7
A2: Growth mindset, self-belief and attitudes, by level of performance
A3: Change in the following student self-beliefs and attitudes when they disagreed or strongly disagreed that "your intelligence is something about you that you can’t change very much", by level of performance in mathematics; OECD average
A34: Notes: differences are accounting for gender and students' and schools' socio-economic profile.
A35: The socio-economic profile is measured by the PISA index of economic, social and cultural status (ESCS).
A36: Differences that are statistically significant are shown in a darker tone (see Reader’s Guide).
A37: Source: OECD, PISA 2022 Database, Tables B.19 and B.21.
B40: Index of mathematics self-efficacy: Formal and applied mathematics | D40: Index of persistence | F40: Index of curiosity
B41: Significant change | C41: Non-significant change | D41: Significant change | E41: Non-significant change | F41: Significant change | G41: Non-significant change
B42: Index dif. | C42: Index dif. | D42: Index dif. | E42: Index dif. | F42: Index dif. | G42: Index dif.
A43: Low performers (Below Level 2) | B43: #N/A | C43: 0.0058372682 | D43: #N/A | E43: 0.016026579 | F43: -0.045064136 | G43: #N/A
A44: Mid performers (Between Levels 2 to 4) | B44: 0.11910756 | C44: #N/A | D44: 0.13942312 | E44: #N/A | F44: 0.1175023 | G44: #N/A
A45: Top performers (Level 5 and above) | B45: #N/A | C45: -0.025847541 | D45: 0.14285748 | E45: #N/A | F45: 0.10448048 | G45: #N/A

Sheet Figure 8
A1: Figure 8
A2: Growth mindset and confidence in self-directed learning, by level of performance
A3: Change in self-directed learning when students disagreed or strongly disagreed that "your intelligence is something about you that you can’t change very much", by level of performance in mathematics
A76: Notes: Only countries and economies with available data are shown.
A77: Statistically significant differences are shown in a darker tone (see Reader’s Guide).
A78: Countries and economies are ranked in descending order of the difference for mid performers (between Levels 2 to 4) in mathematics.
A79: Source: OECD, PISA 2022 Database, Table B.19.
B85: Low performers | D85: Mid performers | F85: Top performers
B86: Significant change | C86: Non-significant change | D86: Significant change | E86: Non-significant change | F86: Significant change | G86: Non-significant change
B87: Index dif. | C87: Index dif. | D87: Index dif. | E87: Index dif. | F87: Index dif. | G87: Index dif. | I87: min | J87: max | K87: low | L87: med | O87: spacing | P87: positive error low | Q87: negative error low | R87: positive error med | S87: negative error med | T87: CNT | U87: Sub-nat entities
A88: New Zealand* | B88: #N/A | C88: 0.047820695 | D88: 0.31848094 | E88: #N/A | F88: #N/A | G88: 0.090449318 | I88: 0.047820695 | J88: 0.31848094 | K88: 0.047820695 | L88: 0.31848094 | N88: 0.27066024 | O88: 70.5 | P88: 0.27066024 | Q88: 0 | R88: 0 | S88: 0.27066024 | T88: -0.3 | U88: #N/A
A89: Chinese Taipei | B89: #N/A | C89: 0.26138371 | D89: 0.31623968 | E89: #N/A | F89: 0.24129364 | G89: #N/A | I89: 0.24129364 | J89: 0.31623968 | K89: 0.26138371 | L89: 0.31623968 | N89: 0.074946046 | O89: 69.5 | P89: 0 | Q89: 0 | R89: 0 | S89: 0.074946046 | T89: #N/A | U89: -0.3
A90: Ireland* | B90: 0.2490527 | C90: #N/A | D90: 0.30900428 | E90: #N/A | F90: #N/A | G90: 0.21384075 | I90: 0.21384075 | J90: 0.30900428 | K90: 0.2490527 | L90: 0.30900428 | N90: 0.095163524 | O90: 68.5 | P90: 0 | Q90: 0 | R90: 0 | S90: 0.095163524 | T90: -0.3 | U90: #N/A
A91: United Kingdom* | B91: #N/A | C91: 0.12836768 | D91: 0.26127946 | E91: #N/A | F91: 0.19779553 | G91: #N/A | I91: 0.12836768 | J91: 0.26127946 | K91: 0.12836768 | L91: 0.26127946 | N91: 0.13291179 | O91: 67.5 | P91: 0.13291179 | Q91: 0 | R91: 0 | S91: 0.13291179 | T91: -0.3 | U91: #N/A
A92: Hong Kong (China)* | B92: #N/A | C92: 0.12275821 | D92: 0.24899629 | E92: #N/A | F92: 0.1584014 | G92: #N/A | I92: 0.12275821 | J92: 0.24899629 | K92: 0.12275821 | L92: 0.24899629 | N92: 0.12623808 | O92: 66.5 | P92: 0.12623808 | Q92: 0 | R92: 0 | S92: 0.12623808 | T92: #N/A | U92: -0.3
A93: Korea | B93: #N/A | C93: 0.049238712 | D93: 0.24696347 | E93: #N/A | F93: #N/A | G93: 0.054735444 | I93: 0.049238712 | J93: 0.24696347 | K93: 0.049238712 | L93: 0.24696347 | N93: 0.19772476 | O93: 65.5 | P93: 0.19772476 | Q93: 0 | R93: 0 | S93: 0.19772476 | T93: -0.3 | U93: #N/A
A94: Austria | B94: #N/A | C94: 0.029711066 | D94: 0.23068129 | E94: #N/A | F94: #N/A | G94: 0.17213711 | I94: 0.029711066 | J94: 0.23068129 | K94: 0.029711066 | L94: 0.23068129 | N94: 0.20097022 | O94: 64.5 | P94: 0.20097022 | Q94: 0 | R94: 0 | S94: 0.20097022 | T94: -0.3 | U94: #N/A
A95: Macao (China) | B95: #N/A | C95: 0.075189002 | D95: 0.21582562 | E95: #N/A | F95: 0.23579183 | G95: #N/A | I95: 0.075189002 | J95: 0.23579183 | K95: 0.075189002 | L95: 0.21582562 | N95: 0.16060283 | O95: 63.5 | P95: 0.16060283 | Q95: 0 | R95: 0 | S95: 0 | T95: #N/A | U95: -0.3
A96: Japan | B96: 0.32071003 | C96: #N/A | D96: 0.21471603 | E96: #N/A | F96: 0.30291289 | G96: #N/A | I96: 0.21471603 | J96: 0.32071003 | K96: 0.32071003 | L96: 0.21471603 | N96: 0.105994 | O96: 62.5 | P96: 0 | Q96: 0.105994 | R96: 0.105994 | S96: 0 | T96: -0.3 | U96: #N/A
A97: Uruguay | B97: #N/A | C97: -0.11193083 | D97: 0.21340922 | E97: #N/A | F97: #N/A | G97: #N/A | I97: -0.11193083 | J97: 0.21340922 | K97: -0.11193083 | L97: 0.21340922 | N97: 0.32534005 | O97: 61.5 | P97: 0.32534005 | Q97: 0 | R97: 0 | S97: 0.32534005 | T97: -0.3 | U97: #N/A
A98: Germany | B98: #N/A | C98: -0.003909634 | D98: 0.17547064 | E98: #N/A | F98: #N/A | G98: 0.042005997 | I98: -0.003909634 | J98: 0.17547064 | K98: -0.003909634 | L98: 0.17547064 | N98: 0.17938027 | O98: 60.5 | P98: 0.17938027 | Q98: 0 | R98: 0 | S98: 0.17938027 | T98: -0.3 | U98: #N/A
A99: Peru | B99: #N/A | C99: -0.050814118 | D99: 0.16102998 | E99: #N/A | F99: #N/A | G99: #N/A | I99: -0.050814118 | J99: 0.16102998 | K99: -0.050814118 | L99: 0.16102998 | N99: 0.2118441 | O99: 59.5 | P99: 0.2118441 | Q99: 0 | R99: 0 | S99: 0.2118441 | T99: -0.3 | U99: #N/A
A100: Thailand | B100: #N/A | C100: -0.076468132 | D100: 0.15870078 | E100: #N/A | F100: #N/A | G100: -0.096648946 | I100: -0.096648946 | J100: 0.15870078 | K100: -0.076468132 | L100: 0.15870078 | N100: 0.25534973 | O100: 58.5 | P100: 0 | Q100: 0 | R100: 0 | S100: 0.25534973 | T100: -0.3 | U100: #N/A
A101: Australia* | B101: #N/A | C101: 0.02943329 | D101: 0.15757734 | E101: #N/A | F101: 0.24058868 | G101: #N/A | I101: 0.02943329 | J101: 0.24058868 | K101: 0.02943329 | L101: 0.15757734 | N101: 0.21115539 | O101: 57.5 | P101: 0.21115539 | Q101: 0 | R101: 0 | S101: 0 | T101: -0.3 | U101: #N/A
A102: United States* | B102: #N/A | C102: 0.019696871 | D102: 0.15535812 | E102: #N/A | F102: 0.38924754 | G102: #N/A | I102: 0.019696871 | J102: 0.38924754 | K102: 0.019696871 | L102: 0.15535812 | N102: 0.36955067 | O102: 56.5 | P102: 0.36955067 | Q102: 0 | R102: 0 | S102: 0 | T102: -0.3 | U102: #N/A
A103: Canada* | B103: #N/A | C103: 0.090227872 | D103: 0.13087961 | E103: #N/A | F103: #N/A | G103: 0.054421965 | I103: 0.054421965 | J103: 0.13087961 | K103: 0.090227872 | L103: 0.13087961 | N103: 0.076457646 | O103: 55.5 | P103: 0 | Q103: 0 | R103: 0 | S103: 0.076457646 | T103: -0.3 | U103: #N/A
A104: Latvia* | B104: #N/A | C104: -0.055390719 | D104: 0.12350327 | E104: #N/A | F104: #N/A | G104: 0.13941519 | I104: -0.055390719 | J104: 0.13941519 | K104: -0.055390719 | L104: 0.12350327 | N104: 0.19480591 | O104: 54.5 | P104: 0.19480591 | Q104: 0 | R104: 0 | S104: 0 | T104: -0.3 | U104: #N/A
A105: Mexico | B105: -0.16907419 | C105: #N/A | D105: 0.11967754 | E105: #N/A | F105: #N/A | G105: #N/A | I105: -0.16907419 | J105: 0.11967754 | K105: -0.16907419 | L105: 0.11967754 | N105: 0.28875173 | O105: 53.5 | P105: 0.28875173 | Q105: 0 | R105: 0 | S105: 0.28875173 | T105: -0.3 | U105: #N/A
A106: Morocco | B106: -0.13772157 | C106: #N/A | D106: #N/A | E106: 0.1189118 | F106: #N/A | G106: #N/A | I106: -0.13772157 | J106: 0.1189118 | K106: -0.13772157 | L106: 0.1189118 | N106: 0.25663337 | O106: 52.5 | P106: 0.25663337 | Q106: 0 | R106: 0 | S106: 0.25663337 | T106: -0.3 | U106: #N/A
A107: Uzbekistan | B107: -0.14497662 | C107: #N/A | D107: #N/A | E107: 0.11817681 | F107: #N/A | G107: #N/A | I107: -0.14497662 | J107: 0.11817681 | K107: -0.14497662 | L107: 0.11817681 | N107: 0.26315343 | O107: 51.5 | P107: 0.26315343 | Q107: 0 | R107: 0 | S107: 0.26315343 | T107: -0.3 | U107: #N/A
A108: Baku (Azerbaijan) | B108: #N/A | C108: -0.14834331 | D108: #N/A | E108: 0.11789588 | F108: #N/A | G108: #N/A | I108: -0.14834331 | J108: 0.11789588 | K108: -0.14834331 | L108: 0.11789588 | N108: 0.26623919 | O108: 50.5 | P108: 0.26623919 | Q108: 0 | R108: 0 | S108: 0.26623919 | T108: #N/A | U108: -0.3
A109: El Salvador | B109: -0.10417663 | C109: #N/A | D109: #N/A | E109: 0.11684404 | F109: #N/A | G109: #N/A | I109: -0.10417663 | J109: 0.11684404 | K109: -0.10417663 | L109: 0.11684404 | N109: 0.22102067 | O109: 49.5 | P109: 0.22102067 | Q109: 0 | R109: 0 | S109: 0.22102067 | T109: -0.3 | U109: #N/A
A110: Malta | B110: #N/A | C110: 0.0380514 | D110: #N/A | E110: 0.11515402 | F110: #N/A | G110: 0.2071725 | I110: 0.0380514 | J110: 0.2071725 | K110: 0.0380514 | L110: 0.11515402 | N110: 0.1691211 | O110: 48.5 | P110: 0.1691211 | Q110: 0 | R110: 0 | S110: 0 | T110: -0.3 | U110: #N/A
A111: OECD average | B111: #N/A | C111: -0.015330456 | D111: 0.11255633 | E111: #N/A | F111: 0.13783605 | G111: #N/A | I111: -0.015330456 | J111: 0.13783605 | K111: -0.015330456 | L111: 0.11255633 | N111: 0.15316651 | O111: 47.5 | P111: 0.15316651 | Q111: 0 | R111: 0 | S111: 0 | T111: -0.3 | U111: #N/A
A112: Türkiye | B112: #N/A | C112: -0.04038706 | D112: 0.105654 | E112: #N/A | F112: #N/A | G112: 0.12819044 | I112: -0.04038706 | J112: 0.12819044 | K112: -0.04038706 | L112: 0.105654 | N112: 0.1685775 | O112: 46.5 | P112: 0.1685775 | Q112: 0 | R112: 0 | S112: 0 | T112: -0.3 | U112: #N/A
A113: Brunei Darussalam | B113: #N/A | C113: -0.028102845 | D113: 0.10473759 | E113: #N/A | F113: #N/A | G113: -0.0045834114 | I113: -0.028102845 | J113: 0.10473759 | K113: -0.028102845 | L113: 0.10473759 | N113: 0.13284044 | O113: 45.5 | P113: 0.13284044 | Q113: 0 | R113: 0 | S113: 0.13284044 | T113: -0.3 | U113: #N/A
A114: United Arab Emirates | B114: -0.20544752 | C114: #N/A | D114: 0.10382134 | E114: #N/A | F114: #N/A | G114: 0.094169192 | I114: -0.20544752 | J114: 0.10382134 | K114: -0.20544752 | L114: 0.10382134 | N114: 0.30926886 | O114: 44.5 | P114: 0.30926886 | Q114: 0 | R114: 0 | S114: 0.30926886 | T114: -0.3 | U114: #N/A
A115: Serbia | B115: #N/A | C115: -0.035183784 | D115: #N/A | E115: 0.10137168 | F115: #N/A | G115: 0.090425596 | I115: -0.035183784 | J115: 0.10137168 | K115: -0.035183784 | L115: 0.10137168 | N115: 0.13655547 | O115: 43.5 | P115: 0.13655547 | Q115: 0 | R115: 0 | S115: 0.13655547 | T115: -0.3 | U115: #N/A
A116: Finland | B116: #N/A | C116: -0.065622747 | D116: 0.099076256 | E116: #N/A | F116: #N/A | G116: -0.017517313 | I116: -0.065622747 | J116: 0.099076256 | K116: -0.065622747 | L116: 0.099076256 | N116: 0.164699 | O116: 42.5 | P116: 0.164699 | Q116: 0 | R116: 0 | S116: 0.164699 | T116: -0.3 | U116: #N/A
A117: Qatar | B117: -0.26107985 | C117: #N/A | D117: #N/A | E117: 0.09525995 | F117: #N/A | G117: 0.11442585 | I117: -0.26107985 | J117: 0.11442585 | K117: -0.26107985 | L117: 0.09525995 | N117: 0.37550569 | O117: 41.5 | P117: 0.37550569 | Q117: 0 | R117: 0 | S117: 0 | T117: -0.3 | U117: #N/A
...

Sheet Figure_9
A1: Figure_9
A2: Relationship between growth mindset, performance in mathematics and mathematics anxiety
A3: Score-point difference in mathematics and difference in the index of mathematics anxiety when students report a growth mindset
A47: Note: Only countries and economies with available data are shown.
A48: Differences are accounting for students' and schools' socio-economic profile.
A49: The socio-economic profile is measured by the PISA index of economic, social and cultural status (ESCS).
A50: Source: OECD, PISA 2022 Database, Tables B.12 and B.19.
A52: Information on data for Cyprus: https://oe.cd/cyprus-disclaimer
B53: Performance in mathematics | C53: Mathematics anxiety
B54: Score dif. | C54: Dif.
A55: Albania | B55: 0.11881423 | C55: 0.086698205 | E55: -0.4 | F55: 17.57544
A56: United Arab Emirates | B56: 34.417429 | C56: -0.12051088 | E56: 0.1 | F56: 17.57544
A57: Argentina | B57: 15.578029 | C57: -0.0032352808
A58: Australia* | B58: 45.418576 | C58: -0.19286972 | E58: -10 | F58: -0.12301378
A59: Austria | B59: 17.255558 | C59: -0.16676182 | E59: 50 | F59: -0.12301378
A60: Belgium | B60: 7.9736027 | C60: -0.10308621
A61: Bulgaria | B61: 4.7023801 | C61: 0.066557864
A62: Brazil | B62: 28.510063 | C62: -0.11457623
A63: Brunei Darussalam | B63: 22.451838 | C63: -0.16124061
A64: Canada* | B64: 29.953909 | C64: -0.1562426
A65: Switzerland | B65: 7.7283902 | C65: -0.062725033
A66: Chile | B66: 29.773602 | C66: -0.090726634
A67: Colombia | B67: 19.295426 | C67: -0.033725016
A68: Czechia | B68: 6.7794811 | C68: -0.15496732
A69: Germany | B69: 7.5582467 | C69: -0.10452364
A70: Denmark* | B70: 25.788927 | C70: -0.27935468
A71: Dominican Republic | B71: 4.3645091 | C71: -0.0097532108
... A128: OECD average | B128: 17.57544 | C128: -0.12301378

Sheet Figure 10
A1: Figure 10
A2: Growth mindset and performance in mathematics, by level of socio-emotional skills
A3: Change in mathematics performance when students disagreed or strongly disagreed that "your intelligence is something about you that you can’t change very much", by the quarter of the following indices; OECD average
A34: Notes: differences are accounting for gender and students' and schools' socio-economic profile.
A35: The socio-economic profile is measured by the PISA index of economic, social and cultural status (ESCS).
A36: All differences are statistically significant (see Reader’s Guide).
A37: Source: OECD, PISA 2022 Database, Tables B.29, B.30, B.31 and B.32.
C40: Bottom quarter | E40: Top quarter
C41: Significant change | D41: Non-significant change | E41: Significant change | F41: Non-significant change
C42: Score dif. | D42: Score dif. | E42: Score dif. | F42: Score dif.
A43: Enablers | B43: Index of curiosity | C43: 7.9645834 | D43: #N/A | E43: 19.478836 | F43: #N/A
B44: Index of persistence | C44: 9.7962227 | D44: #N/A | E44: 18.565228 | F44: #N/A
A45: Regulators | B45: Index of emotional control | C45: 18.986942 | D45: #N/A | E45: 12.368236 | F45: #N/A
B46: Index of stress resistance | C46: 18.275 | D46: #N/A | E46: 14.17903 | F46: #N/A

Sheet Figure 11
A1: Figure 11
A2: Growth mindset and teacher practices, by level of performance
A3: Change in the following teacher practices when students disagreed or strongly disagreed that "your intelligence is something about you that you can’t change very much", by level of performance in mathematics; OECD average
A34: Notes: differences are accounting for gender and students' and schools' socio-economic profile.
A35: The socio-economic profile is measured by the PISA index of economic, social and cultural status (ESCS).
A36: Differences that are not statistically significant are shown in a lighter tone (see Reader’s Guide).
A37: Source: OECD, PISA 2022 Database, Table B.23.
B40: Index of teacher support in mathematics | D40: Index of cognitive activation in mathematics: Foster reasoning | F40: Index of quality of student-teacher relationships | H40: Quality of mathematics instruction
B41: Significant change | C41: Non-significant change | D41: Significant change | E41: Non-significant change | F41: Significant change | G41: Non-significant change | H41: Significant change | I41: Non-significant change
B42: Index dif. | C42: Index dif. | D42: Index dif. | E42: Index dif. | F42: Index dif. | G42: Index dif. | H42: Index dif. | I42: Index dif.
A43: Low performers (Below Level 2) | B43: 0.045095224 | C43: #N/A | D43: -0.068123303 | E43: #N/A | F43: -0.024898252 | G43: #N/A | H43: #N/A | I43: 0.023598213
A44: Mid performers (Between Levels 2 to 4) | B44: 0.098206677 | C44: #N/A | D44: 0.031097541 | E44: #N/A | F44: 0.10350753 | G44: #N/A | H44: 0.18957368 | I44: #N/A
A45: Top performers (Level 5 and above) | B45: 0.11040851 | C45: #N/A | D45: 0.04574129 | E45: #N/A | F45: 0.14800778 | G45: #N/A | H45: 0.16745619 | I45: #N/A

Sheet Figure 12
A1: Figure 12
A2: Growth mindset and performance in mathematics, by level of students' cognitive activation
A3: Change in mathematics performance when students disagreed or strongly disagreed that "your intelligence is something about you that you can’t change very much", by the quarter of index of cognitive activation in mathematics: Foster reasoning
A76: Notes: Only countries and economies with available data are shown.
A77: Differences are accounting for gender and students' and schools' socio-economic profile.
A78: The socio-economic profile is measured by the PISA index of economic, social and cultural status (ESCS).
A79: Statistically significant differences between bottom and top quarters are shown in a darker tone (see Reader’s Guide).
A80: Countries and economies are ranked in descending order of the difference between bottom and top quarters (top - bottom).
A81: Source: OECD, PISA 2022 Database, Table B.28.
B87: Bottom quarter | D87: Top quarter
B88: Significant change | C88: Non-significant change | D88: Significant change | E88: Non-significant change
B89: Score dif. | C89: Score dif. | D89: Score dif. | E89: Score dif. | M89: spacing | N89: positive error | O89: negative error | P89: CNT | Q89: Sub-nat entities
A90: United Arab Emirates | B90: 11.775782 | C90: #N/A | D90: 53.827076 | E90: #N/A | L90: 42.051294 | M90: 74.5 | N90: 0 | O90: 42.051294 | P90: -20 | Q90: #N/A
A91: Albania | B91: -12.694369 | C91: #N/A | D91: 15.633175 | E91: #N/A | L91: 28.327544 | M91: 73.5 | N91: 0 | O91: 28.327544 | P91: -20 | Q91: #N/A
A92: Montenegro | B92: -11.307876 | C92: #N/A | D92: 16.431347 | E92: #N/A | L92: 27.739223 | M92: 72.5 | N92: 0 | O92: 27.739223 | P92: -20 | Q92: #N/A
A93: Thailand | B93: 2.9681849 | C93: #N/A | D93: 30.313177 | E93: #N/A | L93: 27.344992 | M93: 71.5 | N93: 0 | O93: 27.344992 | P93: -20 | Q93: #N/A
A94: Baku (Azerbaijan) | B94: -9.4219952 | C94: #N/A | D94: 17.239805 | E94: #N/A | L94: 26.6618 | M94: 70.5 | N94: 0 | O94: 26.6618 | P94: #N/A | Q94: -20
A95: Malaysia | B95: -11.497313 | C95: #N/A | D95: 13.182033 | E95: #N/A | L95: 24.679345 | M95: 69.5 | N95: 0 | O95: 24.679345 | P95: -20 | Q95: #N/A
A96: Moldova | B96: -13.859578 | C96: #N/A | D96: 10.441613 | E96: #N/A | L96: 24.301191 | M96: 68.5 | N96: 0 | O96: 24.301191 | P96: -20 | Q96: #N/A
A97: Qatar | B97: 4.6239505 | C97: #N/A | D97: 27.763575 | E97: #N/A | L97: 23.139624 | M97: 67.5 | N97: 0 | O97: 23.139624 | P97: -20 | Q97: #N/A
A98: Philippines | B98: -10.589425 | C98: #N/A | D98: 12.343305 | E98: #N/A | L98: 22.93273 | M98: 66.5 | N98: 0 | O98: 22.93273 | P98: -20 | Q98: #N/A
A99: Saudi Arabia | B99: -2.5599253 | C99: #N/A | D99: 19.626095 | E99: #N/A | L99: 22.18602 | M99: 65.5 | N99: 0 | O99: 22.18602 | P99: -20 | Q99: #N/A
A100: Kosovo | B100: -2.17731 | C100: #N/A | D100: 18.535955 | E100: #N/A | L100: 20.713265 | M100: 64.5 | N100: 0 | O100: 20.713265 | P100: #N/A | Q100: -20
A101: Georgia | B101: 3.5295565 | C101: #N/A | D101: 23.954491 | E101: #N/A | L101: 20.424934 | M101: 63.5 | N101: 0 | O101: 20.424934 | P101: -20 | Q101: #N/A
A102: Uruguay | B102: 8.2272568 | C102: #N/A | D102: 27.242537 | E102: #N/A | L102: 19.01528 | M102: 62.5 | N102: 0 | O102: 19.01528 | P102: -20 | Q102: #N/A
A103: United States* | B103: 32.528366 | C103: #N/A | D103: 50.998043 | E103: #N/A | L103: 18.469677 | M103: 61.5 | N103: 0 | O103: 18.469677 | P103: -20 | Q103: #N/A
A104: Dominican Republic | B104: -2.5252779 | C104: #N/A | D104: 14.024356 | E104: #N/A | L104: 16.549634 | M104: 60.5 | N104: 0 | O104: 16.549634 | P104: -20 | Q104: #N/A
A105: Peru | B105: 14.728064 | C105: #N/A | D105: 30.924143 | E105: #N/A | L105: 16.196079 | M105: 59.5 | N105: 0 | O105: 16.196079 | P105: -20 | Q105: #N/A
A106: North Macedonia | B106: 10.686811 | C106: #N/A | D106: 26.741568 | E106: #N/A | L106: 16.054756 | M106: 58.5 | N106: 0 | O106: 16.054756 | P106: -20 | Q106: #N/A
A107: Ukrainian regions (18 of 27) | B107: #N/A | C107: 13.321114 | D107: #N/A | E107: 29.029423 | L107: 15.708309 | M107: 57.5 | N107: 0 | O107: 15.708309 | P107: #N/A | Q107: -20
A108: Latvia* | B108: 9.8220158 | C108: #N/A | D108: 25.496077 | E108: #N/A | L108: 15.674061 | M108: 56.5 | N108: 0 | O108: 15.674061 | P108: -20 | Q108: #N/A
A109: Slovak Republic | B109: -5.731113 | C109: #N/A | D109: 9.2277298 | E109: #N/A | L109: 14.958843 | M109: 55.5 | N109: 0 | O109: 14.958843 | P109: -20 | Q109: #N/A
A110: United Kingdom* | B110: #N/A | C110: 31.134552 | D110: #N/A | E110: 46.020428 | L110: 14.885876 | M110: 54.5 | N110: 0 | O110: 14.885876 | P110: -20 | Q110: #N/A
A111: El Salvador | B111: -4.4996905 | C111: #N/A | D111: 10.299145 | E111: #N/A | L111: 14.798835 | M111: 53.5 | N111: 0 | O111: 14.798835 | P111: -20 | Q111: #N/A
A112: Mexico | B112: 10.969055 | C112: #N/A | D112: 25.258383 | E112: #N/A | L112: 14.289328 | M112: 52.5 | N112: 0 | O112: 14.289328 | P112: -20 | Q112: #N/A
A113: Palestinian Authority | B113: -7.0804496 | C113: #N/A | D113: 7.0457845 | E113: #N/A | L113: 14.126234 | M113: 51.5 | N113: 0 | O113: 14.126234 | P113: #N/A | Q113: -20
A114: Chile | B114: 23.428904 | C114: #N/A | D114: 37.487484 | E114: #N/A | L114: 14.05858 | M114: 50.5 | N114: 0 | O114: 14.05858 | P114: -20 | Q114: #N/A
A115: Morocco | B115: -4.2558165 | C115: #N/A | D115: 9.7640781 | E115: #N/A | L115: 14.019895 | M115: 49.5 | N115: 0 | O115: 14.019895 | P115: -20 | Q115: #N/A
A116: Argentina | B116: 8.1949511 | C116: #N/A | D116: 21.910946 | E116: #N/A | L116: 13.715995 | M116: 48.5 | N116: 0 | O116: 13.715995 | P116: -20 | Q116: #N/A
A117: Macao (China) | B117: #N/A | C117: -2.8876083 | D117: #N/A | E117: 9.82722 | L117: 12.714828 | M117: 47.5 | N117: 0 | O117: 12.714828 | P117: #N/A | Q117: -20
...

Sheet Figure 13
A1: Figure 13
A2: School concentration of growth mindset
A3: Percentage of students in schools with low/high concentration¹ of those who disagree or strongly disagree that "your intelligence is something about you that you can't change very much"
A76: 1. A low (high) concentration is defined as a value that is half standard deviation below (above) the average within the student’s country or economy.
A77: Note: Only countries and economies with available data are shown.
A78: Countries and economies are ranked in descending order of the difference between share of students in schools with high and low concentration of growth mindset.
A79: Source: OECD, PISA 2022 Database, Table B.6.
B85: Schools with low growth mindset concentration | C85: Schools with high growth mindset concentration
B86: Significant change | C86: Significant change
B87: % | C87: % | K87: spacing | L87: positive error | M87: negative error | N87: CNT | O87: Sub-nat entities
A88: Austria | B88: 24.157458 | C88: 34.277515 | J88: 10.120057 | K88: 75.5 | L88: 0 | M88: 10.120057 | N88: 10 | O88: #N/A
A89: North Macedonia | B89: 26.976691 | C89: 35.984362 | J89: 9.0076716 | K89: 74.5 | L89: 0 | M89: 9.0076716 | N89: 10 | O89: #N/A
A90: United States* | B90: 24.359043 | C90: 32.550281 | J90: 8.1912386 | K90: 73.5 | L90: 0 | M90: 8.1912386 | N90: 10 | O90: #N/A
A91: Montenegro | B91: 17.919636 | C91: 25.505715 | J91: 7.5860794 | K91: 72.5 | L91: 0 | M91: 7.5860794 | N91: 10 | O91: #N/A
A92: Estonia | B92: 23.151132 | C92: 30.08559 | J92: 6.9344581 | K92: 71.5 | L92: 0 | M92: 6.9344581 | N92: 10 | O92: #N/A
A93: Germany | B93: 25.465206 | C93: 31.938473 | J93: 6.4732675 | K93: 70.5 | L93: 0 | M93: 6.4732675 | N93: 10 | O93: #N/A
A94: Slovak Republic | B94: 25.407599 | C94: 31.582739 | J94: 6.1751399 | K94: 69.5 | L94: 0 | M94: 6.1751399 | N94: 10 | O94: #N/A
A95: Argentina | B95: 28.145348 | C95: 33.329913 | J95: 5.1845642 | K95: 68.5 | L95: 0 | M95: 5.1845642 | N95: 10 | O95: #N/A
A96: France | B96: 24.177759 | C96: 29.224189 | J96: 5.0464302 | K96: 67.5 | L96: 0 | M96: 5.0464302 | N96: 10 | O96: #N/A
A97: Ireland* | B97: 28.544536 | C97: 33.58225 | J97: 5.0377139 | K97: 66.5 | L97: 0 | M97: 5.0377139 | N97: 10 | O97: #N/A
A98: Kazakhstan | B98: 25.433448 | C98: 30.427903 | J98: 4.994455 | K98: 65.5 | L98: 0 | M98: 4.994455 | N98: 10 | O98: #N/A
A99: Serbia | B99: 24.247859 | C99: 29.166727 | J99: 4.9188687 | K99: 64.5 | L99: 0 | M99: 4.9188687 | N99: 10 | O99: #N/A
... A109: Lithuania | B109: 27.307384 | C109: 29.751016 | J109: 2.4436322 | K109: 54.5 | L109: 0 | M109: 2.4436322 | N109: 10 | O109: #N/A
A110: Chinese Taipei | B110: 28.107402 | C110: 30.417943 | J110: 2.310541 | K110: 53.5 | L110: 0 | M110: 2.310541 | N110: #N/A | O110: 10
A111: New Zealand* | B111: 28.218066 | C111: 30.347774 | J111: 2.1297073 | K111: 52.5 | L111: 0 | M111: 2.1297073 | N111: 10 | O111: #N/A
A112: Georgia | B112: 26.897712 | C112: 28.783698 | J112: 1.8859866 | K112: 51.5 | L112: 0 | M112: 1.8859866 | N112: 10 | O112: #N/A
A113: OECD average | B113: 28.756559 | C113: 30.571518 | J113: 1.8149592 | K113: 50.5 | L113: 0 | M113: 1.8149592 | N113: 10 | O113: #N/A
A114: Mongolia | B114: 26.873861 | C114: 28.648878 | J114: 1.7750168 | K114: 49.5 | L114: 0 | M114: 1.7750168 | N114: 10 | O114: #N/A
A115: Brazil | B115: 27.556782 | C115: 29.157218 | J115: 1.6004354 | K115: 48.5 | L115: 0 | M115: 1.6004354 | N115: 10 | O115: #N/A
A116: Iceland | B116: 30.252952 | C116: 31.76344 | J116: 1.5104873 | K116: 47.5 | L116: 0 | M116: 1.5104873 | N116: 10 | O116: #N/A
A117: Palestinian Authority | B117: 28.17135 | C117: 29.656523 | J117: 1.4851732 | K117: 46.5 | L117: 0 | M117: 1.4851732 | N117: #N/A | O117: 10
